Workbook

Sheet Задание
A1: SQL
A2: Необходимо написать sql запросы для выгрузки данных из базы ms sql используя следующие таблицы и учитывая их структуру:
A4: warehouses (справочник складов)
A5: Наименование | B5: Тип поля | C5: Описание | D5: Пример
A6: warehouse_id | B6: integer | C6: идентификатор склада | D6: 1020652676
A7: name | B7: varchar | C7: наименование склада | D7: Рублевское шоссе
A8: city | B8: varchar | C8: город | D8: Москва
A9: date_open | B9: date | C9: дата открытия склада | D9: 44440
A10: date_close | B10: date | C10: дата закрытия склада | D10: null
A12: product (справочник товаров)
A13: product_id | B13: integer | C13: идентификатор товара | D13: 3577634400
A14: name | B14: varchar | C14: наименование товара | D14: Морс Самокат клюквенный, 500 мл
A15: group1 | B15: varchar | C15: группа товаров 1 уровня | D15: Безалкогольные напитки
A16: group2 | B16: varchar | C16: группа товаров 2 уровня | D16: Соковая продукция
A17: group3 | B17: varchar | C17: группа товаров 3 уровня | D17: Морсы
A18: weight | B18: decimal | C18: вес товара | D18: 0.55
A19: shelf_life | B19: integer | C19: срок годности товара в днях | D19: 180
A21: orders (заказы)
A22: order_id | B22: integer | C22: идентификатор заказа | D22: 1045687455
A23: warehouse_id | B23: integer | C23: идентификатор склада | D23: 1020652676
A24: user_id | B24: integer | C24: идентификатор клиента | D24: 4557094039
A25: date | B25: datetime | C25: дата и время создания заказа | D25: 44440.57
A26: paid_amount | B26: decimal | C26: сумма заказа | D26: 1565
A27: quantity | B27: decimal | C27: количество единиц товаров в заказе | D27: 12
A29: order_line (состав заказа)
A30: order_id | B30: integer | C30: идентификатор заказа | D30: 1045687455
A31: date | B31: datetime | C31: дата и время создания заказа | D31: 44440.57
A32: warehouse_id | B32: integer | C32: идентификатор склада | D32: 1020652676
A33: product_id | B33: integer | C33: идентификатор товара | D33: 3577634400
A34: price | B34: decimal | C34: цена продажи | D34: 89.9
A35: regular_price | B35: decimal | C35: регулярная цена | D35: 89.9
A36: cost_price | B36: decimal | C36: цена в себестоимости | D36: 80.5
A37: quantity | B37: decimal | C37: количество единиц проданных товаров | D37: 2
A38: paid_amount | B38: decimal | C38: сумма продаж | D38: 179.8
A40: lost (потери)
A41: date | B41: datetime | C41: дата и время проведения потерь | D41: 44440.57
A42: warehouse_id | B42: integer | C42: идентификатор склада | D42: 1020652676
A43: product_id | B43: integer | C43: идентификатор товара | D43: 3577634400
A44: item_id | B44: integer | C44: идентификатор статьи потерь. Например, списание по сроку годности - 146 | D44: 146
A45: quantity | B45: decimal | C45: потери в количестве | D45: 3
...

Sheet Лист1
A1: Дата | B1: № недели | C1: Территория | D1: Товарооборот, шт | E1: Товарооборот, руб | F1: Товарооборот в себестоимости | G1: Потери, руб | H1: Количество складов | I1: Количество заказов | J1: Количество клиентов
A2: 43982 | B2: =_xlfn.ISOWEEKNUM(A2) -> 22 | C2: Самара | D2: 7944 | E2: 623971.5 | F2: 565363.02 | G2: 64235.457 | H2: {=INDEX(Таблица1[Количество складов],MATCH(1,(Таблица1[Дата]=Лист1!A2)*(Таблица1[Территория]=Лист1!C2),0))} -> 15 | I2: {=INDEX(Таблица1[Количество заказов],MATCH(1,(Таблица1[Дата]=Лист1!A2)*(Таблица1[Территория]=Лист1!C2),0))} -> 441 | J2: {=INDEX(Таблица1[Количество клиентов],MATCH(1,(Таблица1[Дата]=Лист1!A2)*(Таблица1[Территория]=Лист1!C2),0))} -> 368
A3: 43981 | B3: =_xlfn.ISOWEEKNUM(A3) -> 22 | C3: Самара | D3: 10029 | E3: 787101 | F3: 707654.63 | G3: 112379.27 | H3: {=INDEX(Таблица1[Количество складов],MATCH(1,(Таблица1[Дата]=Лист1!A3)*(Таблица1[Территория]=Лист1!C3),0))} -> 15 | I3: {=INDEX(Таблица1[Количество заказов],MATCH(1,(Таблица1[Дата]=Лист1!A3)*(Таблица1[Территория]=Лист1!C3),0))} -> 490 | J3: {=INDEX(Таблица1[Количество клиентов],MATCH(1,(Таблица1[Дата]=Лист1!A3)*(Таблица1[Территория]=Лист1!C3),0))} -> 409
A4: 43979 | B4: =_xlfn.ISOWEEKNUM(A4) -> 22 | C4: Самара | D4: 8536.5 | E4: 643944 | F4: 640961.69 | G4: 61475.592 | H4: {=INDEX(Таблица1[Количество складов],MATCH(1,(Таблица1[Дата]=Лист1!A4)*(Таблица1[Территория]=Лист1!C4),0))} -> 15 | I4: {=INDEX(Таблица1[Количество заказов],MATCH(1,(Таблица1[Дата]=Лист1!A4)*(Таблица1[Территория]=Лист1!C4),0))} -> 464 | J4: {=INDEX(Таблица1[Количество клиентов],MATCH(1,(Таблица1[Дата]=Лист1!A4)*(Таблица1[Территория]=Лист1!C4),0))} -> 390
A5: 43967 | B5: =_xlfn.ISOWEEKNUM(A5) -> 20 | C5: Кемерово | D5: 38947.5 | E5: 3395892 | F5: 2740255.2 | G5: 294361.08 | H5: {=INDEX(Таблица1[Количество складов],MATCH(1,(Таблица1[Дата]=Лист1!A5)*(Таблица1[Территория]=Лист1!C5),0))} -> 21 | I5: {=INDEX(Таблица1[Количество заказов],MATCH(1,(Таблица1[Дата]=Лист1!A5)*(Таблица1[Территория]=Лист1!C5),0))} -> 2145 | J5: {=INDEX(Таблица1[Количество клиентов],MATCH(1,(Таблица1[Дата]=Лист1!A5)*(Таблица1[Территория]=Лист1!C5),0))} -> 1947
A6: 43970 | B6: =_xlfn.ISOWEEKNUM(A6) -> 21 | C6: Кемерово | D6: 31842 | E6: 2771116.5 | F6: 2269371.4 | G6: 328803.85 | H6: {=INDEX(Таблица1[Количество складов],MATCH(1,(Таблица1[Дата]=Лист1!A6)*(Таблица1[Территория]=Лист1!C6),0))} -> 21 | I6: {=INDEX(Таблица1[Количество заказов],MATCH(1,(Таблица1[Дата]=Лист1!A6)*(Таблица1[Территория]=Лист1!C6),0))} -> 1860 | J6: {=INDEX(Таблица1[Количество клиентов],MATCH(1,(Таблица1[Дата]=Лист1!A6)*(Таблица1[Территория]=Лист1!C6),0))} -> 1704
A7: 43968 | B7: =_xlfn.ISOWEEKNUM(A7) -> 20 | C7: Кемерово | D7: 32023.5 | E7: 2882458.5 | F7: 2290967 | G7: 246817.75 | H7: {=INDEX(Таблица1[Количество складов],MATCH(1,(Таблица1[Дата]=Лист1!A7)*(Таблица1[Территория]=Лист1!C7),0))} -> 21 | I7: {=INDEX(Таблица1[Количество заказов],MATCH(1,(Таблица1[Дата]=Лист1!A7)*(Таблица1[Территория]=Лист1!C7),0))} -> 1874 | J7: {=INDEX(Таблица1[Количество клиентов],MATCH(1,(Таблица1[Дата]=Лист1!A7)*(Таблица1[Территория]=Лист1!C7),0))} -> 1705
A8: 43960 | B8: =_xlfn.ISOWEEKNUM(A8) -> 19 | C8: Кемерово | D8: 31147.5 | E8: 2831019 | F8: 2261296.3 | G8: 225845 | H8: {=INDEX(Таблица1[Количество складов],MATCH(1,(Таблица1[Дата]=Лист1!A8)*(Таблица1[Территория]=Лист1!C8),0))} -> 21 | I8: {=INDEX(Таблица1[Количество заказов],MATCH(1,(Таблица1[Дата]=Лист1!A8)*(Таблица1[Территория]=Лист1!C8),0))} -> 1735 | J8: {=INDEX(Таблица1[Количество клиентов],MATCH(1,(Таблица1[Дата]=Лист1!A8)*(Таблица1[Территория]=Лист1!C8),0))} -> 1568
A9: 43955 | B9: =_xlfn.ISOWEEKNUM(A9) -> 19 | C9: Кемерово | D9: 25566 | E9: 2372310 | F9: 1875929.9 | G9: 280340.17 | H9: {=INDEX(Таблица1[Количество складов],MATCH(1,(Таблица1[Дата]=Лист1!A9)*(Таблица1[Территория]=Лист1!C9),0))} -> 20 | I9: {=INDEX(Таблица1[Количество заказов],MATCH(1,(Таблица1[Дата]=Лист1!A9)*(Таблица1[Территория]=Лист1!C9),0))} -> 1519 | J9: {=INDEX(Таблица1[Количество клиентов],MATCH(1,(Таблица1[Дата]=Лист1!A9)*(Таблица1[Территория]=Лист1!C9),0))} -> 1372
A10: 43950 | B10: =_xlfn.ISOWEEKNUM(A10) -> 18 | C10: Кемерово | D10: 29319 | E10: 2623480.5 | F10: 2115482 | G10: 139204.6 | H10: {=INDEX(Таблица1[Количество складов],MATCH(1,(Таблица1[Дата]=Лист1!A10)*(Таблица1[Территория]=Лист1!C10),0))} -> 18 | I10: {=INDEX(Таблица1[Количество заказов],MATCH(1,(Таблица1[Дата]=Лист1!A10)*(Таблица1[Территория]=Лист1!C10),0))} -> 1684 | J10: {=INDEX(Таблица1[Количество клиентов],MATCH(1,(Таблица1[Дата]=Лист1!A10)*(Таблица1[Территория]=Лист1!C10),0))} -> 1528
A11: 43953 | B11: =_xlfn.ISOWEEKNUM(A11) -> 18 | C11: Кемерово | D11: 29031 | E11: 2711247 | F11: 2165434.9 | G11: 185484.17 | H11: {=INDEX(Таблица1[Количество складов],MATCH(1,(Таблица1[Дата]=Лист1!A11)*(Таблица1[Территория]=Лист1!C11),0))} -> 18 | I11: {=INDEX(Таблица1[Количество заказов],MATCH(1,(Таблица1[Дата]=Лист1!A11)*(Таблица1[Территория]=Лист1!C11),0))} -> 1708 | J11: {=INDEX(Таблица1[Количество клиентов],MATCH(1,(Таблица1[Дата]=Лист1!A11)*(Таблица1[Территория]=Лист1!C11),0))} -> 1534
A12: 43977 | B12: =_xlfn.ISOWEEKNUM(A12) -> 22 | C12: Кемерово | D12: 33423 | E12: 2970330 | F12: 2395998.4 | G12: 259067.64 | H12: {=INDEX(Таблица1[Количество складов],MATCH(1,(Таблица1[Дата]=Лист1!A12)*(Таблица1[Территория]=Лист1!C12),0))} -> 20 | I12: {=INDEX(Таблица1[Количество заказов],MATCH(1,(Таблица1[Дата]=Лист1!A12)*(Таблица1[Территория]=Лист1!C12),0))} -> 2044 | J12: {=INDEX(Таблица1[Количество клиентов],MATCH(1,(Таблица1[Дата]=Лист1!A12)*(Таблица1[Территория]=Лист1!C12),0))} -> 1863
A13: 43952 | B13: =_xlfn.ISOWEEKNUM(A13) -> 18 | C13: Кемерово | D13: 32487 | E13: 3031254 | F13: 2397503.4 | G13: 232079.85 | H13: {=INDEX(Таблица1[Количество складов],MATCH(1,(Таблица1[Дата]=Лист1!A13)*(Таблица1[Территория]=Лист1!C13),0))} -> 18 | I13: {=INDEX(Таблица1[Количество заказов],MATCH(1,(Таблица1[Дата]=Лист1!A13)*(Таблица1[Территория]=Лист1!C13),0))} -> 1826 | J13: {=INDEX(Таблица1[Количество клиентов],MATCH(1,(Таблица1[Дата]=Лист1!A13)*(Таблица1[Территория]=Лист1!C13),0))} -> 1633
... A505: 43983 | B505: =_xlfn.ISOWEEKNUM(A505) -> 23 | C505: Новосибирск | D505: 14238 | E505: 1293219 | F505: 1006008.1 | G505: 129348.29 | H505: {=INDEX(Таблица1[Количество складов],MATCH(1,(Таблица1[Дата]=Лист1!A505)*(Таблица1[Территория]=Лист1!C505),0))} -> 18 | I505: {=INDEX(Таблица1[Количество заказов],MATCH(1,(Таблица1[Дата]=Лист1!A505)*(Таблица1[Территория]=Лист1!C505),0))} -> 923 | J505: {=INDEX(Таблица1[Количество клиентов],MATCH(1,(Таблица1[Дата]=Лист1!A505)*(Таблица1[Территория]=Лист1!C505),0))} -> 824

Sheet Задание 2
A1: № недели | B1: 22
L2: Полная последняя неделя - 22
A3: Территория | B3: Товарооборот, шт | C3: Товарооборот, руб | D3: Товарооборот в себестоимости | E3: Потери, руб | F3: Количество складов | G3: Количество заказов | H3: Количество клиентов | I3: Наценка | J3: Доходность | L3: Доля продаж | M3: Товарооборот на 1 склад
A4: Волгоград | B4: 540592.5 | C4: 46485094 | D4: 36573773 | E4: 1215586 | F4: 256 | G4: 36734 | H4: 33925 | I4: 0.27099534 | J4: 0.21321505 | L4: =C4/$C$22 -> 0.044034424 | M4: =C4/F4 -> 181582.4
A5: Екатеринбург | B5: 598485 | C5: 50729186 | D5: 39434705 | E5: 808350.57 | F5: 217 | G5: 39634 | H5: 36856 | I5: 0.28640967 | J5: 0.22264266 | L5: =C5/$C$22 -> 0.048054769 | M5: =C5/F5 -> 233775.05
A6: Казань | B6: 296626.5 | C6: 27495690 | D6: 21336710 | E6: 1213933.1 | F6: 152 | G6: 17544 | H6: 16025 | I6: 0.28865647 | J6: 0.223998 | L6: =C6/$C$22 -> 0.026046131 | M6: =C6/F6 -> 180892.7
A7: Кемерово | B7: 249246 | C7: 22579281 | D7: 18021288 | E7: 1857394 | F7: 141 | G7: 15075 | H7: 13784 | I7: 0.25292273 | J7: 0.20186618 | L7: =C7/$C$22 -> 0.021388913 | M7: =C7/F7 -> 160136.74
A8: Краснодар | B8: 210733.5 | C8: 18595773 | D8: 14841990 | E8: 677023.79 | F8: 141 | G8: 13755 | H8: 12541 | I8: 0.2529164 | J8: 0.20186215 | L8: =C8/$C$22 -> 0.017615413 | M8: =C8/F8 -> 131884.91
A9: Москва Восток | B9: 1498459.5 | C9: 151451013 | D9: 1.1271038e+08 | E9: 2011267.9 | F9: 378 | G9: 94045 | H9: 87485 | I9: 0.34371838 | J9: 0.25579644 | L9: =C9/$C$22 -> 0.14346659 | M9: =C9/F9 -> 400664.06
A10: Москва Запад | B10: 1552795.5 | C10: 1.5785721e+08 | D10: 1.1703237e+08 | E10: 1929112.4 | F10: 414 | G10: 98369 | H10: 91327 | I10: 0.34883377 | J10: 0.2586188 | L10: =C10/$C$22 -> 0.14953506 | M10: =C10/F10 -> 381297.62
A11: Нижний Новгород | B11: 232813.5 | C11: 21605704 | D11: 17167430 | E11: 1168237.7 | F11: 140 | G11: 14974 | H11: 13289 | I11: 0.25852877 | J11: 0.20542143 | L11: =C11/$C$22 -> 0.020466663 | M11: =C11/F11 -> 154326.46
A12: Новосибирск | B12: 114889.5 | C12: 9909624 | D12: 8086120.6 | E12: 663214.79 | F12: 126 | G12: 7144 | H12: 6380 | I12: 0.22551029 | J12: 0.18401338 | L12: =C12/$C$22 -> 0.0093871937 | M12: =C12/F12 -> 78647.81
A13: Пермь | B13: 133758 | C13: 11902053 | D13: 9600312.1 | E13: 1516859.6 | F13: 119 | G13: 8761 | H13: 7787 | I13: 0.23975688 | J13: 0.19339024 | L13: =C13/$C$22 -> 0.011274583 | M13: =C13/F13 -> 100017.25
A14: Ростов-на-Дону | B14: 102393 | C14: 9328845 | D14: 7482668 | E14: 1225600 | F14: 109 | G14: 6278 | H14: 5490 | I14: 0.2467271 | J14: 0.19789984 | L14: =C14/$C$22 -> 0.0088370331 | M14: =C14/F14 -> 85585.734
A15: Самара | B15: 34860 | C15: 2706253.5 | D15: 2515464.5 | E15: 321104.95 | F15: 60 | G15: 1795 | H15: 1496 | I15: 0.075846444 | J15: 0.070499321 | L15: =C15/$C$22 -> 0.0025635812 | M15: =C15/F15 -> 45104.225
... A21: Уфа | B21: 5127 | C21: 468835.5 | D21: 412625.89 | E21: 8642.3769 | F21: 6 | G21: 261 | H21: 188 | I21: 0.13622416 | J21: 0.11989197 | L21: =C21/$C$22 -> 0.00044411873 | M21: =C21/F21 -> 78139.25
A22: Общий итог | B22: 10730598 | C22: 1.0556535e+09 | D22: 7.9686085e+08 | E22: 23475787 | F22: 4151 | G22: 644177 | H22: 594900 | I22: 0.32476518 | J22: 0.24514924

Sheet Лист2
A1: Дата | B1: Территория | C1: Количество складов | D1: Количество заказов | E1: Количество клиентов
A2: 43949 | B2: Волгоград | C2: 36 | D2: 4923 | E2: 4560
A3: 43949 | B3: Екатеринбург | C3: 31 | D3: 5465 | E3: 5096
A4: 43949 | B4: Казань | C4: 19 | D4: 1846 | E4: 1681
A5: 43949 | B5: Кемерово | C5: 18 | D5: 1539 | E5: 1404
A6: 43949 | B6: Краснодар | C6: 18 | D6: 1505 | E6: 1368
A7: 43949 | B7: Москва Восток | C7: 54 | D7: 12306 | E7: 11532
A8: 43949 | B8: Москва Запад | C8: 59 | D8: 12943 | E8: 12072
A9: 43949 | B9: Нижний Новгород | C9: 17 | D9: 1439 | E9: 1265
A10: 43949 | B10: Новосибирск | C10: 15 | D10: 636 | E10: 547
A11: 43949 | B11: Пермь | C11: 15 | D11: 780 | E11: 690
A12: 43949 | B12: Санкт-Петербург Север | C12: 125 | D12: 20914 | E12: 19479
A13: 43949 | B13: Санкт-Петербург Юг | C13: 128 | D13: 16450 | E13: 15320
... A505: 43983 | B505: Уфа | C505: 6 | D505: 237 | E505: 175
